Workbook

Sheet How to Fill

Sheet Define Event Report
A1: Vendor | B1: Model | C1: Settings | D1: Settings Value | E1: Equipment Type (e.g., Process, Metrology)
A2: TL | B2: FTGM2 | C2: DATAIDType | D2: U4 | E2: Metrology
C3: VIDType | D3: U4
C4: CEIDType | D4: U4
C5: RPTIDType | D5: U4
C6: ECIDType | D6: U4
C7: ALIDType | D7: U4
A10: Index | B10: SEMI | C10: Event | D10: AliasName_MappingWithTSMC | E10: TAP->TCS Report | F10: CEID | G10: Valid_DV | H10: DVID | I10: Data_Type | J10: Event Name (SECS Manual) | K10: VID Name (SECS Manual) | L10: Remark
A11: 1 | B11: E30 | C11: OffLine | D11: ToolModeChange_OffLine | F11: 1 | G11: ControlState | H11: =IFERROR(IF(VLOOKUP($G11, 'Enter DVID'!$A$1:$C$61, 2, FALSE)="", "", VLOOKUP($G11, 'Enter DVID'!$A$1:$C$61, 2, FALSE)), "") -> 6 | I11: =IFERROR(IF(VLOOKUP($G11, 'Enter DVID'!$A$1:$C$61, 3, FALSE)="", "", VLOOKUP($G11, 'Enter DVID'!$A$1:$C$61, 3, FALSE)), "") -> U1 | J11: GEM_Equipment_Off_Line | K11: =IFERROR(IF(VLOOKUP($G11, 'Enter DVID'!$A$1:$D$61, 4, FALSE)="", "", VLOOKUP($G11, 'Enter DVID'!$A$1:$D$61, 4, FALSE)), "") -> SYS_CONTROL_STATE
G12: EventName | H12: =IFERROR(IF(VLOOKUP($G12, 'Enter DVID'!$A$1:$C$61, 2, FALSE)="", "", VLOOKUP($G12, 'Enter DVID'!$A$1:$C$61, 2, FALSE)), "") | I12: =IFERROR(IF(VLOOKUP($G12, 'Enter DVID'!$A$1:$C$61, 3, FALSE)="", "", VLOOKUP($G12, 'Enter DVID'!$A$1:$C$61, 3, FALSE)), "") | K12: =IFERROR(IF(VLOOKUP($G12, 'Enter DVID'!$A$1:$D$61, 4, FALSE)="", "", VLOOKUP($G12, 'Enter DVID'!$A$1:$D$61, 4, FALSE)), "")
G13: CLOCK | H13: =IFERROR(IF(VLOOKUP($G13, 'Enter DVID'!$A$1:$C$61, 2, FALSE)="", "", VLOOKUP($G13, 'Enter DVID'!$A$1:$C$61, 2, FALSE)), "") -> 3 | I13: =IFERROR(IF(VLOOKUP($G13, 'Enter DVID'!$A$1:$C$61, 3, FALSE)="", "", VLOOKUP($G13, 'Enter DVID'!$A$1:$C$61, 3, FALSE)), "") -> A | K13: =IFERROR(IF(VLOOKUP($G13, 'Enter DVID'!$A$1:$D$61, 4, FALSE)="", "", VLOOKUP($G13, 'Enter DVID'!$A$1:$D$61, 4, FALSE)), "") -> SYS_CLOCK
A15: Index | B15: SEMI | C15: Event | D15: AliasName_MappingWithTSMC | E15: TAP->TCS Report | F15: CEID | G15: Valid_DV | H15: DVID | I15: Data_Type | J15: Event Name (SECS Manual) | K15: VID Name (SECS Manual) | L15: Remark
A16: 2 | B16: E30 | C16: Remote | D16: ToolModeChange_Remote | F16: 3 | G16: ControlState | H16: =IFERROR(IF(VLOOKUP($G16, 'Enter DVID'!$A$1:$C$61, 2, FALSE)="", "", VLOOKUP($G16, 'Enter DVID'!$A$1:$C$61, 2, FALSE)), "") -> 6 | I16: =IFERROR(IF(VLOOKUP($G16, 'Enter DVID'!$A$1:$C$61, 3, FALSE)="", "", VLOOKUP($G16, 'Enter DVID'!$A$1:$C$61, 3, FALSE)), "") -> U1 | J16: GEM_Control_State_Remote | K16: =IFERROR(IF(VLOOKUP($G16, 'Enter DVID'!$A$1:$D$61, 4, FALSE)="", "", VLOOKUP($G16, 'Enter DVID'!$A$1:$D$61, 4, FALSE)), "") -> SYS_CONTROL_STATE
G17: EventName | H17: =IFERROR(IF(VLOOKUP($G17, 'Enter DVID'!$A$1:$C$61, 2, FALSE)="", "", VLOOKUP($G17, 'Enter DVID'!$A$1:$C$61, 2, FALSE)), "") | I17: =IFERROR(IF(VLOOKUP($G17, 'Enter DVID'!$A$1:$C$61, 3, FALSE)="", "", VLOOKUP($G17, 'Enter DVID'!$A$1:$C$61, 3, FALSE)), "") | K17: =IFERROR(IF(VLOOKUP($G17, 'Enter DVID'!$A$1:$D$61, 4, FALSE)="", "", VLOOKUP($G17, 'Enter DVID'!$A$1:$D$61, 4, FALSE)), "")
G18: CLOCK | H18: =IFERROR(IF(VLOOKUP($G18, 'Enter DVID'!$A$1:$C$61, 2, FALSE)="", "", VLOOKUP($G18, 'Enter DVID'!$A$1:$C$61, 2, FALSE)), "") -> 3 | I18: =IFERROR(IF(VLOOKUP($G18, 'Enter DVID'!$A$1:$C$61, 3, FALSE)="", "", VLOOKUP($G18, 'Enter DVID'!$A$1:$C$61, 3, FALSE)), "") -> A | K18: =IFERROR(IF(VLOOKUP($G18, 'Enter DVID'!$A$1:$D$61, 4, FALSE)="", "", VLOOKUP($G18, 'Enter DVID'!$A$1:$D$61, 4, FALSE)), "") -> SYS_CLOCK
A20: Index | B20: SEMI | C20: Event | D20: AliasName_MappingWithTSMC | E20: TAP->TCS Report | F20: CEID | G20: Valid_DV | H20: DVID | I20: Data_Type | J20: Event Name (SECS Manual) | K20: VID Name (SECS Manual) | L20: Remark
A21: 3 | B21: E30 | C21: Local | D21: ToolModeChange_Local | F21: 2 | G21: ControlState | H21: =IFERROR(IF(VLOOKUP($G21, 'Enter DVID'!$A$1:$C$61, 2, FALSE)="", "", VLOOKUP($G21, 'Enter DVID'!$A$1:$C$61, 2, FALSE)), "") -> 6 | I21: =IFERROR(IF(VLOOKUP($G21, 'Enter DVID'!$A$1:$C$61, 3, FALSE)="", "", VLOOKUP($G21, 'Enter DVID'!$A$1:$C$61, 3, FALSE)), "") -> U1 | J21: GEM_Control_State_Local | K21: =IFERROR(IF(VLOOKUP($G21, 'Enter DVID'!$A$1:$D$61, 4, FALSE)="", "", VLOOKUP($G21, 'Enter DVID'!$A$1:$D$61, 4, FALSE)), "") -> SYS_CONTROL_STATE
G22: EventName | H22: =IFERROR(IF(VLOOKUP($G22, 'Enter DVID'!$A$1:$C$61, 2, FALSE)="", "", VLOOKUP($G22, 'Enter DVID'!$A$1:$C$61, 2, FALSE)), "") | I22: =IFERROR(IF(VLOOKUP($G22, 'Enter DVID'!$A$1:$C$61, 3, FALSE)="", "", VLOOKUP($G22, 'Enter DVID'!$A$1:$C$61, 3, FALSE)), "") | K22: =IFERROR(IF(VLOOKUP($G22, 'Enter DVID'!$A$1:$D$61, 4, FALSE)="", "", VLOOKUP($G22, 'Enter DVID'!$A$1:$D$61, 4, FALSE)), "")
G23: CLOCK | H23: =IFERROR(IF(VLOOKUP($G23, 'Enter DVID'!$A$1:$C$61, 2, FALSE)="", "", VLOOKUP($G23, 'Enter DVID'!$A$1:$C$61, 2, FALSE)), "") -> 3 | I23: =IFERROR(IF(VLOOKUP($G23, 'Enter DVID'!$A$1:$C$61, 3, FALSE)="", "", VLOOKUP($G23, 'Enter DVID'!$A$1:$C$61, 3, FALSE)), "") -> A | K23: =IFERROR(IF(VLOOKUP($G23, 'Enter DVID'!$A$1:$D$61, 4, FALSE)="", "", VLOOKUP($G23, 'Enter DVID'!$A$1:$D$61, 4, FALSE)), "") -> SYS_CLOCK
A25: Index | B25: SEMI | C25: Event | D25: AliasName_MappingWithTSMC | E25: TAP->TCS Report | F25: CEID | G25: Valid_DV | H25: DVID | I25: Data_Type | J25: Event Name (SECS Manual) | K25: VID Name (SECS Manual) | L25: Remark
A26: 4 | B26: E30 | C26: EquipmentChange | D26: ECChange | F26: 6300 | G26: ECChangeID | H26: =IFERROR(IF(VLOOKUP($G26, 'Enter DVID'!$A$1:$C$61, 2, FALSE)="", "", VLOOKUP($G26, 'Enter DVID'!$A$1:$C$61, 2, FALSE)), "") -> 47 | I26: =IFERROR(IF(VLOOKUP($G26, 'Enter DVID'!$A$1:$C$61, 3, FALSE)="", "", VLOOKUP($G26, 'Enter DVID'!$A$1:$C$61, 3, FALSE)), "") -> U4 | J26: EquipmentConstChange | K26: =IFERROR(IF(VLOOKUP($G26, 'Enter DVID'!$A$1:$D$61, 4, FALSE)="", "", VLOOKUP($G26, 'Enter DVID'!$A$1:$D$61, 4, FALSE)), "") -> SYS_ECID_CHANGED
A28: Index | B28: SEMI | C28: Event | D28: AliasName_MappingWithTSMC | E28: TAP->TCS Report | F28: CEID | G28: Valid_DV | H28: DVID | I28: Data_Type | J28: Event Name (SECS Manual) | K28: VID Name (SECS Manual) | L28: Remark
A29: 5 | B29: E30 | C29: ProcessProgramChange by operator-initiated | D29: GemPPChangeEvent | F29: 6290 | G29: PPChangeName | H29: =IFERROR(IF(VLOOKUP($G29, 'Enter DVID'!$A$1:$C$61, 2, FALSE)="", "", VLOOKUP($G29, 'Enter DVID'!$A$1:$C$61, 2, FALSE)), "") -> 41 | I29: =IFERROR(IF(VLOOKUP($G29, 'Enter DVID'!$A$1:$C$61, 3, FALSE)="", "", VLOOKUP($G29, 'Enter DVID'!$A$1:$C$61, 3, FALSE)), "") -> A | J29: PPChange | K29: =IFERROR(IF(VLOOKUP($G29, 'Enter DVID'!$A$1:$D$61, 4, FALSE)="", "", VLOOKUP($G29, 'Enter DVID'!$A$1:$D$61, 4, FALSE)), "") -> SYS_PP_CHANGE_NAME
G30: PPChangeStatus | H30: =IFERROR(IF(VLOOKUP($G30, 'Enter DVID'!$A$1:$C$61, 2, FALSE)="", "", VLOOKUP($G30, 'Enter DVID'!$A$1:$C$61, 2, FALSE)), "") -> 42 | I30: =IFERROR(IF(VLOOKUP($G30, 'Enter DVID'!$A$1:$C$61, 3, FALSE)="", "", VLOOKUP($G30, 'Enter DVID'!$A$1:$C$61, 3, FALSE)), "") -> U1 | K30: =IFERROR(IF(VLOOKUP($G30, 'Enter DVID'!$A$1:$D$61, 4, FALSE)="", "", VLOOKUP($G30, 'Enter DVID'!$A$1:$D$61, 4, FALSE)), "") -> SYS_PP_CHANGE_STATUS
G31: PPChangeStatusText | H31: =IFERROR(IF(VLOOKUP($G31, 'Enter DVID'!$A$1:$C$61, 2, FALSE)="", "", VLOOKUP($G31, 'Enter DVID'!$A$1:$C$61, 2, FALSE)), "") -> 4142 | I31: =IFERROR(IF(VLOOKUP($G31, 'Enter DVID'!$A$1:$C$61, 3, FALSE)="", "", VLOOKUP($G31, 'Enter DVID'!$A$1:$C$61, 3, FALSE)), "") -> A | K31: =IFERROR(IF(VLOOKUP($G31, 'Enter DVID'!$A$1:$D$61, 4, FALSE)="", "", VLOOKUP($G31, 'Enter DVID'!$A$1:$D$61, 4, FALSE)), "") -> SYS_PP_CHANGE_STATUS_TEXT
A33: Index | B33: SEMI | C33: Event | D33: AliasName_MappingWithTSMC | E33: TAP->TCS Report | F33: CEID | G33: Valid_DV | H33: DVID | I33: Data_Type | J33: Event Name (SECS Manual) | K33: VID Name (SECS Manual) | L33: Remark
A34: 6 | B34: E87 | C34: UNDEFINE->OUT OF SERVICE | D34: UndefineOutOfService | F34: 221 | G34: PortID | H34: =IFERROR(IF(VLOOKUP($G34, 'Enter DVID'!$A$1:$C$61, 2, FALSE)="", "", VLOOKUP($G34, 'Enter DVID'!$A$1:$C$61, 2, FALSE)), "") -> 2001 | I34: =IFERROR(IF(VLOOKUP($G34, 'Enter DVID'!$A$1:$C$61, 3, FALSE)="", "", VLOOKUP($G34, 'Enter DVID'!$A$1:$C$61, 3, FALSE)), "") -> U1 | J34: CMS_NoStateToOutOfService | K34: =IFERROR(IF(VLOOKUP($G34, 'Enter DVID'!$A$1:$D$61, 4, FALSE)="", "", VLOOKUP($G34, 'Enter DVID'!$A$1:$D$61, 4, FALSE)), "") -> PORTID
G35: PortTransferState | H35: =IFERROR(IF(VLOOKUP($G35, 'Enter DVID'!$A$1:$C$61, 2, FALSE)="", "", VLOOKUP($G35, 'Enter DVID'!$A$1:$C$61, 2, FALSE)), "") -> 2005 | I35: =IFERROR(IF(VLOOKUP($G35, 'Enter DVID'!$A$1:$C$61, 3, FALSE)="", "", VLOOKUP($G35, 'Enter DVID'!$A$1:$C$61, 3, FALSE)), "") -> U1 | K35: =IFERROR(IF(VLOOKUP($G35, 'Enter DVID'!$A$1:$D$61, 4, FALSE)="", "", VLOOKUP($G35, 'Enter DVID'!$A$1:$D$61, 4, FALSE)), "") -> PORTTRANSFERSTATE
G36: EventName | H36: =IFERROR(IF(VLOOKUP($G36, 'Enter DVID'!$A$1:$C$61, 2, FALSE)="", "", VLOOKUP($G36, 'Enter DVID'!$A$1:$C$61, 2, FALSE)), "") | I36: =IFERROR(IF(VLOOKUP($G36, 'Enter DVID'!$A$1:$C$61, 3, FALSE)="", "", VLOOKUP($G36, 'Enter DVID'!$A$1:$C$61, 3, FALSE)), "") | K36: =IFERROR(IF(VLOOKUP($G36, 'Enter DVID'!$A$1:$D$61, 4, FALSE)="", "", VLOOKUP($G36, 'Enter DVID'!$A$1:$D$61, 4, FALSE)), "")
G37: CLOCK | H37: =IFERROR(IF(VLOOKUP($G37, 'Enter DVID'!$A$1:$C$61, 2, FALSE)="", "", VLOOKUP($G37, 'Enter DVID'!$A$1:$C$61, 2, FALSE)), "") -> 3 | I37: =IFERROR(IF(VLOOKUP($G37, 'Enter DVID'!$A$1:$C$61, 3, FALSE)="", "", VLOOKUP($G37, 'Enter DVID'!$A$1:$C$61, 3, FALSE)), "") -> A | K37: =IFERROR(IF(VLOOKUP($G37, 'Enter DVID'!$A$1:$D$61, 4, FALSE)="", "", VLOOKUP($G37, 'Enter DVID'!$A$1:$D$61, 4, FALSE)), "") -> SYS_CLOCK
G38: PortStateInfo | H38: =IFERROR(IF(VLOOKUP($G38, 'Enter DVID'!$A$1:$C$61, 2, FALSE)="", "", VLOOKUP($G38, 'Enter DVID'!$A$1:$C$61, 2, FALSE)), "") -> 463 | I38: =IFERROR(IF(VLOOKUP($G38, 'Enter DVID'!$A$1:$C$61, 3, FALSE)="", "", VLOOKUP($G38, 'Enter DVID'!$A$1:$C$61, 3, FALSE)), "") -> List | K38: =IFERROR(IF(VLOOKUP($G38, 'Enter DVID'!$A$1:$D$61, 4, FALSE)="", "", VLOOKUP($G38, 'Enter DVID'!$A$1:$D$61, 4, FALSE)), "") -> CMS_PORTSTATEINFO
A40: Index | B40: SEMI | C40: Event | D40: AliasName_MappingWithTSMC | E40: TAP->TCS Report | F40: CEID | G40: Valid_DV | H40: DVID | I40: Data_Type | J40: Event Name (SECS Manual) | K40: VID Name (SECS Manual) | L40: Remark
A41: 7 | B41: E87 | C41: IN SERVICE->OUT OF SERVICE | D41: OutOfService | F41: 224 | G41: PortID | H41: =IFERROR(IF(VLOOKUP($G41, 'Enter DVID'!$A$1:$C$61, 2, FALSE)="", "", VLOOKUP($G41, 'Enter DVID'!$A$1:$C$61, 2, FALSE)), "") -> 2001 | I41: =IFERROR(IF(VLOOKUP($G41, 'Enter DVID'!$A$1:$C$61, 3, FALSE)="", "", VLOOKUP($G41, 'Enter DVID'!$A$1:$C$61, 3, FALSE)), "") -> U1 | J41: CMS_InServiceToOutOfService | K41: =IFERROR(IF(VLOOKUP($G41, 'Enter DVID'!$A$1:$D$61, 4, FALSE)="", "", VLOOKUP($G41, 'Enter DVID'!$A$1:$D$61, 4, FALSE)), "") -> PORTID
G42: PortTransferState | H42: =IFERROR(IF(VLOOKUP($G42, 'Enter DVID'!$A$1:$C$61, 2, FALSE)="", "", VLOOKUP($G42, 'Enter DVID'!$A$1:$C$61, 2, FALSE)), "") -> 2005 | I42: =IFERROR(IF(VLOOKUP($G42, 'Enter DVID'!$A$1:$C$61, 3, FALSE)="", "", VLOOKUP($G42, 'Enter DVID'!$A$1:$C$61, 3, FALSE)), "") -> U1 | K42: =IFERROR(IF(VLOOKUP($G42, 'Enter DVID'!$A$1:$D$61, 4, FALSE)="", "", VLOOKUP($G42, 'Enter DVID'!$A$1:$D$61, 4, FALSE)), "") -> PORTTRANSFERSTATE
G43: EventName | H43: =IFERROR(IF(VLOOKUP($G43, 'Enter DVID'!$A$1:$C$61, 2, FALSE)="", "", VLOOKUP($G43, 'Enter DVID'!$A$1:$C$61, 2, FALSE)), "") | I43: =IFERROR(IF(VLOOKUP($G43, 'Enter DVID'!$A$1:$C$61, 3, FALSE)="", "", VLOOKUP($G43, 'Enter DVID'!$A$1:$C$61, 3, FALSE)), "") | K43: =IFERROR(IF(VLOOKUP($G43, 'Enter DVID'!$A$1:$D$61, 4, FALSE)="", "", VLOOKUP($G43, 'Enter DVID'!$A$1:$D$61, 4, FALSE)), "")
G44: CLOCK | H44: =IFERROR(IF(VLOOKUP($G44, 'Enter DVID'!$A$1:$C$61, 2, FALSE)="", "", VLOOKUP($G44, 'Enter DVID'!$A$1:$C$61, 2, FALSE)), "") -> 3 | I44: =IFERROR(IF(VLOOKUP($G44, 'Enter DVID'!$A$1:$C$61, 3, FALSE)="", "", VLOOKUP($G44, 'Enter DVID'!$A$1:$C$61, 3, FALSE)), "") -> A | K44: =IFERROR(IF(VLOOKUP($G44, 'Enter DVID'!$A$1:$D$61, 4, FALSE)="", "", VLOOKUP($G44, 'Enter DVID'!$A$1:$D$61, 4, FALSE)), "") -> SYS_CLOCK
G45: PortStateInfo | H45: =IFERROR(IF(VLOOKUP($G45, 'Enter DVID'!$A$1:$C$61, 2, FALSE)="", "", VLOOKUP($G45, 'Enter DVID'!$A$1:$C$61, 2, FALSE)), "") -> 463 | I45: =IFERROR(IF(VLOOKUP($G45, 'Enter DVID'!$A$1:$C$61, 3, FALSE)="", "", VLOOKUP($G45, 'Enter DVID'!$A$1:$C$61, 3, FALSE)), "") -> List | K45: =IFERROR(IF(VLOOKUP($G45, 'Enter DVID'!$A$1:$D$61, 4, FALSE)="", "", VLOOKUP($G45, 'Enter DVID'!$A$1:$D$61, 4, FALSE)), "") -> CMS_PORTSTATEINFO
A47: Index | B47: SEMI | C47: Event | D47: AliasName_MappingWithTSMC | E47: TAP->TCS Report | F47: CEID | G47: Valid_DV | H47: DVID | I47: Data_Type | J47: Event Name (SECS Manual) | K47: VID Name (SECS Manual) | L47: Remark
A48: 8 | B48: E87 | C48: OUT OF SERVICE->IN SERVICE | D48: InService | F48: 223 | G48: PortID | H48: =IFERROR(IF(VLOOKUP($G48, 'Enter DVID'!$A$1:$C$61, 2, FALSE)="", "", VLOOKUP($G48, 'Enter DVID'!$A$1:$C$61, 2, FALSE)), "") -> 2001 | I48: =IFERROR(IF(VLOOKUP($G48, 'Enter DVID'!$A$1:$C$61, 3, FALSE)="", "", VLOOKUP($G48, 'Enter DVID'!$A$1:$C$61, 3, FALSE)), "") -> U1 | J48: CMS_OutOfServiceToInService | K48: =IFERROR(IF(VLOOKUP($G48, 'Enter DVID'!$A$1:$D$61, 4, FALSE)="", "", VLOOKUP($G48, 'Enter DVID'!$A$1:$D$61, 4, FALSE)), "") -> PORTID
G49: PortTransferState | H49: =IFERROR(IF(VLOOKUP($G49, 'Enter DVID'!$A$1:$C$61, 2, FALSE)="", "", VLOOKUP($G49, 'Enter DVID'!$A$1:$C$61, 2, FALSE)), "") -> 2005 | I49: =IFERROR(IF(VLOOKUP($G49, 'Enter DVID'!$A$1:$C$61, 3, FALSE)="", "", VLOOKUP($G49, 'Enter DVID'!$A$1:$C$61, 3, FALSE)), "") -> U1 | K49: =IFERROR(IF(VLOOKUP($G49, 'Enter DVID'!$A$1:$D$61, 4, FALSE)="", "", VLOOKUP($G49, 'Enter DVID'!$A$1:$D$61, 4, FALSE)), "") -> PORTTRANSFERSTATE
...

Sheet Enter DVID
A1: Valid_DV | B1: DVID (VID) | C1: Data_Type | D1: VID Name (SECS Manual) | E1: Required DVID Description | F1: Tip: 'Must' indicates that this DVID is included in the must-item list of a specific CEID
A2: EventName
A3: CLOCK | B3: 3 | C3: A | D3: SYS_CLOCK
A4: ControlState | B4: 6 | C4: U1 | D4: SYS_CONTROL_STATE | F4: Must
A5: ECChangeID | B5: 47 | C5: U4 | D5: SYS_ECID_CHANGED | E5: ECIDs of the changed equipment constants. | F5: Must
A6: PPChangeName | B6: 41 | C6: A | D6: SYS_PP_CHANGE_NAME | E6: The name (PPID) of the changed recipe. | F6: Must
A7: PPChangeStatus | B7: 42 | C7: U1 | D7: SYS_PP_CHANGE_STATUS | E7: Used to indicate the change status of the recipe, such as created or revised. | F7: Must
A8: PPChangeStatusText | B8: 4142 | C8: A | D8: SYS_PP_CHANGE_STATUS_TEXT | E8: Used to indicate the change status of the recipe, such as created or revised. This item requires the ASCII string type to directly specify the status, without using numeric value mapping.
A9: PortID | B9: 2001 | C9: U1 | D9: PORTID | E9: VID for load port | F9: Must
A10: AccessMode | B10: 2002 | C10: U1 | D10: ACCESSMODE | E10: VID for load port | F10: Must
A11: PortTransferState | B11: 2005 | C11: U1 | D11: PORTTRANSFERSTATE | E11: VID for load port | F11: Must
A12: PortStateInfo | B12: 463 | C12: List | D12: CMS_PORTSTATEINFO | E12: VID for load port
A13: PortAssociationState | B13: 464 | C13: U1 | D13: CMS_PORTASSOCIATIONSTATE | E13: VID for load port
A14: CarrierID | B14: 2000 | C14: A | D14: CARRIERID | E14: VID for carrier attribute | F14: Must
A15: CarrierAccessingStatus | B15: 444 | C15: U1 | D15: CMS_CARRIERACCESSINGSTATUS | E15: VID for carrier attribute | F15: Must
A16: CarrierIDStatus | B16: 443 | C16: U1 | D16: CMS_CARRIERIDSTATUS | E16: VID for carrier attribute
A17: ContentMap | B17: 446 | C17: List | D17: CMS_CONTENTMAP | E17: VID for carrier attribute
A18: SlotMap | B18: 2010 | C18: List | D18: SLOTMAP_LIST | E18: VID for carrier attribute | F18: Must
A19: SlotMapStatus | B19: 2003 | C19: U1 | D19: SLOTMAPSTATUS | E19: VID for carrier attribute
A20: LocationID | B20: 448 | C20: A | D20: CMS_LOCATIONID | E20: VID for carrier attribute | F20: Must
A21: SubStrateCount | B21: 445 | C21: U1 | D21: CMS_SUBSTRATECOUNT | E21: VID for carrier attribute
A22: Usage | B22: 450 | C22: A | D22: CMS_USAGE | E22: VID for carrier attribute
A23: Reason | B23: 2013 | C23: U1 | D23: REASON | E23: VID for carrier attribute
A24: PRJobID | B24: 141 | C24: A | D24: PJ_OBJID | E24: VID for process job attribute | F24: Must
A25: PRJobState | B25: 143 | C25: U1 | D25: PJ_PRJOBSTATE | E25: VID for process job attribute | F25: Must
A26: PRMtlType | B26: 145 | C26: BINARY | D26: PJ_PRMTLTYPE | E26: VID for process job attribute
A27: PRMtlNameList | B27: 144 | C27: List | D27: PJ_PRMTLNAMELIST | E27: VID for process job attribute
A28: PRRecipeID | B28: 148 | C28: A | D28: PJ_RECID | E28: VID for process job attribute | F28: Must
A29: PRRecipeMethod | B29: 147 | C29: U1 | D29: PJ_PRRECIPEMETHOD | E29: VID for process job attribute
A30: PRRecVariableList | B30: 149 | C30: List | D30: PJ_RECVARIABLELIST | E30: VID for process job attribute
A31: PJProcessedWaferCount_CompletedNormally | B31: 4160 | C31: U1 | D31: PJPROCESSEDNORMALLY_WAFERCOUNT | E31: This item requires the processed wafer count for the process job, including only the count of wafers completed normally and excluding abnormal ones, such as aborted or stopped wafers. | F31: Must
A32: AllPRJobsList | B32: 4150 | C32: List | D32: ALLPRJOBSLIST | E32: This item requires a PJID list for all process jobs that have not been completed.
A33: ControlJobID | B33: 241 | C33: A | D33: CJ_OBJID | E33: VID for control job attribute | F33: Must
A34: ControlJobState | B34: 251 | C34: U1 | D34: CJ_STATE | E34: VID for control job attribute | F34: Must
A35: CarrierInputSpec | B35: 242 | C35: List | D35: CJ_CARRIERINPUTSPEC | E35: VID for control job attribute
A36: CurrentPRJob | B36: 243 | C36: List | D36: CJ_CURRENTPRJOB | E36: VID for control job attribute
A37: ProcessOrderMgmt | B37: 249 | C37: U1 | D37: CJ_PROCESSORDERMGMT | E37: VID for control job attribute
A38: PRJobStatusList | B38: 252 | C38: List | D38: CJ_PRJOBSTATUSLIST | E38: VID for control job attribute
A39: CJProcessedWaferCount_CompletedNormally | B39: 4162 | C39: U1 | D39: CJPROCESSEDNORMALLY_WAFERCOUNT | E39: This item requires the processed wafer count for the control job, including only the count of wafers completed normally and excluding abnormal ones, such as aborted or stopped wafers.
A40: CJAbortedWaferCount | B40: 4163 | C40: U1 | D40: CJABORTED_WAFERCCOUNT | E40: This item requires the aborted wafer count for the control job.
...
